<?xml version="1.0"?>

<robot name="automama" xmlns:xacro="http://ros.org/wiki/xacro">
  <origin xyz="0 2 2" rpy="0 0 0"/>
  <!-- <model name='x500_base'> -->
  <self_collide>false</self_collide>
  <static>false</static>


  <link name="chassis">
    <inertial>
      <origin xyz="-0.5 0.3 0.3" rpy="0 0 0"/>
      <mass value="300"/>
      <inertia ixx="0.5" ixy="0.0" ixz="0.0" iyy="0.5" iyz="0.0" izz="0.5"/>
      <!-- <mass>2.0</mass>
      <inertia>
        <ixx>0.02166666666666667</ixx>
        <ixy>0</ixy>
        <ixz>0</ixz>
        <iyy>0.02166666666666667</iyy>
        <iyz>0</iyz>
        <izz>0.04000000000000001</izz>
      </inertia> -->
    </inertial>
    <gravity>true</gravity>
    <!-- <velocity_decay/> -->
    <visual>
      <origin xyz="0 0 .025" rpy="0 0 3.141592654"/>
      <geometry>
        <!-- <cylinder length="0.6" radius="0.2"/> -->
        <mesh filename="package://automama/worlds/base_link.stl" />
        <scale>0.01 0.01 0.01</scale>
      </geometry>
    </visual>
    <collision name="collision">
      <geometry>
        <mesh filename="package://automama/worlds/base_link.stl">
          <scale>0.01 0.01 0.01</scale>
        </mesh>
      </geometry>
    </collision>

  </link>

  
  <link name="Camera1">
    <origin xyz="-1.47 0.4 1.85" rpy="0 0 3.14"/>
    <inertial>
        <mass value="0.1"/>
        <inertia ixx="0.000166667" ixy="0.0" ixz="0.0" iyy="0.000166667" iyz="0.0" izz="0.000166667"/>
    </inertial>
    <visual name="camera1_visual">
      <geometry>
        <box size="0.1 0.1 0.1"/>
      </geometry>
    </visual>
    <collision name="collision">
      <geometry>
        <box size="0.1 0.1 0.1"/>
      </geometry>
    </collision>
  </link>

  <joint name="Camera1_joint" type="fixed">
      <parent link="chassis"/>
      <child link="Camera1"/>
      <origin xyz="-1.47 0.4 1.85" rpy="0 0 0"/>
      <axis xyz="0 0 1"/>
  </joint>

  <link name="Camera2">
    <origin xyz="-1.47 0.05 1.85" rpy="0 0 3.14"/>
    <inertial>
        <mass value="0.1"/>
        <inertia ixx="0.000166667" ixy="0.0" ixz="0.0" iyy="0.000166667" iyz="0.0" izz="0.000166667"/>
    </inertial>
    <visual name="camera2_visual">
      <geometry>
        <box size="0.1 0.1 0.1"/>
      </geometry>
    </visual>
    <collision name="collision">
      <geometry>
        <box size="0.1 0.1 0.1"/>
      </geometry>
    </collision>
  </link>

  <joint name="Camera2_joint" type="fixed">
      <parent link="chassis"/>
      <child link="Camera2"/>
      <origin xyz="-1.47 0.05 1.85" rpy="0 0 0"/>
      <axis xyz="0 0 1"/>
  </joint>

  
  <link name="sensor_box">
    <origin xyz="-1.47 0.225 1.95" rpy="0 0 0"/>
    <inertial>  
      <mass value="0.1"/>
      <inertia ixx="0.000166667" ixy="0.0" ixz="0.0" iyy="0.000166667" iyz="0.0" izz="0.000166667"/>
    </inertial>
    <collision name="sensor_box_collision">
      <geometry>
        <box size="0.1 0.1 0.1"/>
      </geometry>
    </collision>
    <visual name="sensor_box_visual">
      <geometry>
        <box size="0.1 0.1 0.1"/>
      </geometry>
    </visual>
  </link>

  <joint name="sensor_box_joint" type="fixed">
    <parent link="chassis"/>
    <child link="sensor_box"/>
    <origin xyz="-1.47 0.225 1.95" rpy="0 0 0"/>
  </joint>


  <link name="front_left_wheel">
    <inertial>
      <origin xyz="-1.13 -0.15 0.25" rpy="0 0 0"/>
      <mass value="20"/>
      <inertia ixx="1" ixy="0" ixz="0" iyy="1" iyz="0" izz="1"/>
    </inertial>
    <visual name="visual">
      <origin xyz="0 0 0" rpy="0 0 0"/>
      <geometry>
        <mesh filename="package://automama/worlds/wheel1_1.stl"/>
        <scale>0.01 0.01 0.01</scale>
      </geometry>
      <!-- <material name="default">
        <color rgba="0.5 0.5 0.3 1"/>
      </material> -->
    </visual>
    <collision name="collision">
      <origin xyz="0 0 0" rpy="0 0 0"/>
      <geometry>
        <mesh filename="package://automama/worlds/wheel1_1.stl"/>
        <scale>0.01 0.01 0.01</scale>
      </geometry>
      <surface>
        <friction>
          <ode>
            <mu>0.5</mu>
            <mu2>1.0</mu2>
            <fdir1>0 0 1</fdir1>
          </ode>
        </friction>
      </surface>
    </collision>
  </link>

  <joint name="front_left_wheel_joint" type="continuous">
    <origin xyz="-1.13 -0.15 0.25" rpy="0 0 0"/>
    <parent link="front_left_wheel_steering_link"/>
    <child link="front_left_wheel"/>
    <axis xyz="0 1 0"/>
    <!-- <limit lower="-1.79769e+308" upper="1.79769e+308"/> -->
  </joint>


  <link name="front_right_wheel">
    <inertial>
      <origin xyz="-1.13 0.6 0.25" rpy="0 0 0"/>
      <mass value="20"/>
      <inertia ixx="1" ixy="0" ixz="0" iyy="1" iyz="0" izz="1"/>
    </inertial>
    <visual name="visual">
      <origin xyz="0 0 0" rpy="0 0 0"/>
      <geometry>
        <mesh filename="package://automama/worlds/wheel2_1.stl" />
        <scale>0.01 0.01 0.01</scale>
      </geometry>
      <!-- <material name="material">
        <color rgba="0.2 0.2 0.2 1"/>
      </material> -->
    </visual>
    <collision name="collision">
      <origin xyz="0 0 0" rpy="0 0 0"/>
      <geometry>
        <mesh filename="package://automama/worlds/wheel2_1.stl"/>
        <scale>0.01 0.01 0.01</scale>
      </geometry>
      <surface>
        <friction>
          <ode>
            <mu>0.5</mu>
            <mu2>1.0</mu2>
            <fdir1>0 0 1</fdir1>
          </ode>
        </friction>
      </surface>
    </collision>
  </link>

  <joint name="front_right_wheel_joint" type="continuous">
    <origin xyz="-1.13 0.6 0.25" rpy="0 0 0"/>
    <parent link="front_right_wheel_steering_link"/>
    <child link="front_right_wheel"/>
    <axis xyz="0 1 0"/>
    <!-- <limit lower="-1.79769e+308" upper="1.79769e+308"/> -->
  </joint>


  <link name="rear_left_wheel">
    <inertial>
      <origin xyz="0.045 -0.15 0.25" rpy="0 0 0"/>
      <mass value="20"/>
      <inertia ixx="1" ixy="0" ixz="0" iyy="1" iyz="0" izz="1"/>
    </inertial>
    <gravity>true</gravity>
    <visual name="visual">
      <origin xyz="0 0 0" rpy="0 0 0"/>
      <geometry>
        <mesh filename="package://automama/worlds/wheel3_1.stl" />
        <scale>0.01 0.01 0.01</scale>
      </geometry>
      <!-- <material name="material">
        <color rgba="0.2 0.2 0.2 1"/>
      </material> -->
    </visual>
    <collision name="collision">
      <origin xyz="0 0 0" rpy="0 0 0"/>
      <geometry>
        <mesh filename="package://automama/worlds/wheel3_1.stl" />
        <scale>0.01 0.01 0.01</scale>
      </geometry>
      <surface>
        <friction>
          <ode>
            <mu>0.5</mu>
            <mu2>1.0</mu2>
            <fdir1>0 0 1</fdir1>
          </ode>
        </friction>
      </surface>
    </collision>
  </link>

  <joint name="rear_left_wheel_joint" type="continuous">
    <origin xyz="0.045 -0.15 0.25" rpy="0 0 0"/>
    <parent link="chassis"/>
    <child link="rear_left_wheel"/>
    <axis>
      <xyz>0 1 0</xyz>
      <!-- <limit lower="-1.79769e+308" upper="1.79769e+308"/> -->
    </axis>
  </joint>



  <link name="rear_right_wheel">
    <inertial>
      <origin xyz="0.045 0.6 0.25" rpy="0 0 0"/>
      <mass value="20"/>
      <inertia ixx="1" ixy="0" ixz="0" iyy="1" iyz="0" izz="1"/>
    </inertial>
    <visual name="visual">
      <origin xyz="0 0 0" rpy="0 0 0"/>
      <geometry>
        <mesh filename="package://automama/worlds/wheel4_1.stl" />
        <scale>0.01 0.01 0.01</scale>
      </geometry>
      <!-- <material name="material">
        <color rgba="0.2 0.2 0.2 1"/>
      </material> -->
    </visual>
    <collision name="collision">
      <origin xyz="0 0 0" rpy="0 0 0"/>
      <geometry>
        <mesh filename="package://automama/worlds/wheel4_1.stl" />
        <scale>0.01 0.01 0.01</scale>
      </geometry>
      <surface>
        <friction>
          <ode>
            <mu>0.5</mu>
            <mu2>1.0</mu2>
            <fdir1>0 0 1</fdir1>
          </ode>
        </friction>
      </surface>
    </collision>
  </link>

  <joint name="rear_right_wheel_joint" type="continuous">
    <origin xyz="0.045 0.6 0.25" rpy="0 0 0"/>
    <parent link="chassis"/>
    <child link="rear_right_wheel"/>
    <axis>
      <xyz>0 1 0</xyz>
      <!-- <limit lower="-1.79769e+308" upper="1.79769e+308"/> -->
    </axis>
  </joint>


  <link name="front_left_wheel_steering_link">
    <inertial>
      <origin xyz="-1.135 -0.065 0.25" rpy="0 0 0"/>
      <mass value="5"/>
      <inertia ixx="1" ixy="0" ixz="0" iyy="1" iyz="0.0" izz="1"/>
    </inertial>
    <visual name="steering_link_visual">
      <origin xyz="0 0 0" rpy="0 0 0"/>
      <geometry>
        <mesh filename="package://automama/worlds/wheel1_link_1.stl" />
        <scale>0.01 0.01 0.01</scale>
      </geometry>
      <!-- <material name="white"/> -->
    </visual>
  </link>

  <joint name="front_left_wheel_steering_joint" type="revolute">
    <origin xyz="-1.135 -0.065 0.25" rpy="0 0 0"/>
    <parent link="chassis"/>
    <child link="front_left_wheel_steering_link"/>
    <axis xyz="0 0 1"/>
    <limit lower="-0.6" upper="0.6" velocity="1.0" effort="25"/>
  </joint>


  <link name="front_right_wheel_steering_link">
    <inertial>
      <origin xyz="-1.135 0.51 0.25" rpy="0 0 0"/>
      <mass value="5"/>
      <inertia ixx="1" ixy="0" ixz="0" iyy="1" iyz="0.0" izz="1"/>
    </inertial>
    <visual name="steering_link_visual">
      <origin xyz="0 0 0" rpy="0 0 0"/>
      <geometry>
        <mesh filename="package://automama/worlds/wheel2_link_1.stl" />
        <scale>0.01 0.01 0.01</scale>
      </geometry>
      <!-- <material name="white"/> -->
    </visual>
  </link>

  <joint name="front_right_wheel_steering_joint" type="revolute">
    <origin xyz="-1.135 0.51 0.25" rpy="0 0 0"/>
    <parent link="chassis"/>
    <child link="front_right_wheel_steering_link"/>
    <axis xyz="0 0 1"/>
    <limit lower="-0.6" upper="0.6" velocity="1.0" effort="25"/>
  </joint>

</robot>