<?xml version="1.0" ?>
<!--
  Ignition Gazebo Ackermann steering plugin demo

  Try sending commands:

    ign topic -t "/model/vehicle_blue/cmd_vel" -m ignition.msgs.Twist -p "linear: {x: 0.5}, angular: {z: 0.1}"

  Listen to odometry:

    ign topic -e -t /model/vehicle_blue/odometry

-->
<sdf version="1.6">
  <world name="ackermann_steering">

    <physics name="1ms" type="ignored">
      <max_step_size>0.001</max_step_size>
      <real_time_factor>1.0</real_time_factor>
    </physics>
    <plugin
      filename="ignition-gazebo-physics-system"
      name="gz::sim::systems::Physics">
    </plugin>
    <plugin
      filename="ignition-gazebo-sensors-system"
      name="gz::sim::systems::Sensors">
      <render_engine>ogre</render_engine>
    </plugin>
    <plugin
      filename="ignition-gazebo-air-pressure-system"
      name="gz::sim::systems::AirPressure">
    </plugin>
    <plugin
      filename="ignition-gazebo-altimeter-system"
      name="gz::sim::systems::Altimeter">
    </plugin>
    <plugin
      filename="ignition-gazebo-imu-system"
      name="gz::sim::systems::Imu">
    </plugin>
    <plugin
      filename="ignition-gazebo-magnetometer-system"
      name="gz::sim::systems::Magnetometer">
    </plugin>
    <plugin
      filename="ignition-gazebo-forcetorque-system"
      name="ignition::gazebo::systems::ForceTorque">
    </plugin>
    <plugin
      filename="ignition-gazebo-user-commands-system"
      name="gz::sim::systems::UserCommands">
    </plugin>
    <plugin
      filename="ignition-gazebo-scene-broadcaster-system"
      name="gz::sim::systems::SceneBroadcaster">
    </plugin>

    <light type="directional" name="sun">
      <cast_shadows>true</cast_shadows>
      <pose>0 0 5 0 0 0</pose>
      <diffuse>1 1 1 1</diffuse>
      <specular>0.5 0.5 0.5 1</specular>
      <attenuation>
        <range>1000</range>
        <constant>0.9</constant>
        <linear>0.01</linear>
        <quadratic>0.001</quadratic>
      </attenuation>
      <direction>-0.5 0.1 -0.9</direction>
    </light>

    <model name="ground_plane">
      <pose>0 0 -19 0 0 0</pose>
      <static>true</static>
      <link name="link">
        <!-- <collision name="collision">
          <geometry>
            <mesh>
            <uri>sust_map_3.dae</uri>
            <scale>1 1 1</scale>
          </mesh>
          </geometry>
          <surface>
            <friction>
              <ode>
                <mu>50</mu>
              </ode>
            </friction>
          </surface>
        </collision> -->
        <collision name="collision">
          <pose>0 0 18.77 0 0 0</pose>
          <geometry>
            <!-- <mesh>
              <uri>sust_map_4.dae</uri>
              <scale>1 1 1</scale>
            </mesh> -->
            <plane>
              <normal>0 0 1</normal>
              <size>1000 1000</size>
            </plane>
          </geometry>
          <surface>
            <friction>
              <ode>
                <mu>50</mu>
              </ode>
            </friction>
          </surface>
        </collision>
        <visual name="visual">
          <geometry>
            <mesh>
            <uri>sust_map_4.dae</uri>
            <scale>1 1 1</scale>
          </mesh>
          </geometry>
          <!-- <material>
            <ambient>0.8 0.8 0.8 1</ambient>
            <diffuse>0.8 0.8 0.8 1</diffuse>
            <specular>0.8 0.8 0.8 1</specular>
          </material> -->
        </visual>
      </link>
    </model>


    <model name='automama'>
      <pose>0 40 2 0 0 -1.57</pose>

      <link name='chassis'>
        <pose>0 0 0 0 0 0</pose>
        <inertial>
          <pose>-0.5 0.3 0.3 0 0 0</pose>
          <mass>300</mass>
          <inertia>
            <ixx>0.5</ixx>
            <ixy>0</ixy>
            <ixz>0</ixz>
            <iyy>0.5</iyy>
            <iyz>0</iyz>
            <izz>0.5</izz>
          </inertia>
        </inertial>
        <gravity>true</gravity>
        <visual name='visual'>
          <geometry>
          <mesh>
            <scale>.01 .01 .01</scale>
            <uri>base_link.stl</uri>
          </mesh>
        </geometry>
          <material>
            <ambient>0.5 0.5 1.0 1</ambient>
            <diffuse>0.5 0.5 1.0 1</diffuse>
            <specular>0.0 0.0 1.0 1</specular>
          </material>
        </visual>
        <collision name='collision'>
          <!-- <density>7850</density> -->
          <geometry>
          <mesh>
            <scale>.01 .01 .01</scale>
            <uri>base_link.stl</uri>
          </mesh>
        </geometry>
        </collision>
      </link>

      <link name="Camera1">
        <pose>-1.47 0.525 1.85 0 0 3.14</pose>
        <inertial>
          <mass>0.1</mass>
          <inertia>
            <ixx>0.000166667</ixx>
            <iyy>0.000166667</iyy>
            <izz>0.000166667</izz>
          </inertia>
        </inertial>
        <collision name="collision">
          <geometry>
            <box>
              <size>0.1 0.1 0.1</size>
            </box>
          </geometry>
        </collision>
        <visual name="visual">
          <geometry>
            <box>
              <size>0.1 0.1 0.1</size>
            </box>
          </geometry>
        </visual>
        <sensor name="camera1" type="camera">
          <camera>
            <horizontal_fov>1.047</horizontal_fov>
            <image>
              <width>640</width>
              <height>480</height>
            </image>
            <clip>
              <near>0.1</near>
              <far>100</far>
            </clip>
          </camera>
          <always_on>1</always_on>
          <update_rate>30</update_rate>
          <visualize>true</visualize>
          <topic>camera1</topic>
        </sensor>
      </link>
      
      <joint name="Camera1_joint" type="fixed">
        <parent>chassis</parent>
        <child>Camera1</child>
        <pose>-1.47 0.525 1.85 0 0 0</pose>
      </joint>

      <link name="Camera2">
        <pose>-1.47 -0.075 1.85 0 0 3.14</pose>
        <inertial>
          <mass>0.1</mass>
          <inertia>
            <ixx>0.000166667</ixx>
            <iyy>0.000166667</iyy>
            <izz>0.000166667</izz>
          </inertia>
        </inertial>
        <collision name="collision">
          <geometry>
            <box>
              <size>0.1 0.1 0.1</size>
            </box>
          </geometry>
        </collision>
        <visual name="visual">
          <geometry>
            <box>
              <size>0.1 0.1 0.1</size>
            </box>
          </geometry>
        </visual>
        <sensor name="camera2" type="camera">
          <camera>
            <horizontal_fov>1.047</horizontal_fov>
            <image>
              <width>640</width>
              <height>480</height>
            </image>
            <clip>
              <near>0.1</near>
              <far>100</far>
            </clip>
          </camera>
          <always_on>1</always_on>
          <update_rate>30</update_rate>
          <visualize>true</visualize>
          <topic>camera2</topic>
        </sensor>
      </link>
      
      <joint name="Camera2_joint" type="fixed">
        <parent>chassis</parent>
        <child>Camera2</child>
        <pose>-1.47 -0.075 1.85 0 0 0</pose>
      </joint>

      <link name="sensor_box">
        <pose>-1.47 0.225 1.95 0 0 0</pose>
        <inertial>
          <mass>0.1</mass>
          <inertia>
            <ixx>0.000166667</ixx>
            <iyy>0.000166667</iyy>
            <izz>0.000166667</izz>
          </inertia>
        </inertial>
        <collision name="sensor_box_collision">
          <geometry>
            <box>
              <size>0.1 0.1 0.1</size>
            </box>
          </geometry>
        </collision>
        <visual name="sensor_box_visual">
          <geometry>
            <box>
              <size>0.1 0.1 0.1</size>
            </box>
          </geometry>
        </visual>
        <sensor name="altimeter" type="altimeter">
          <always_on>1</always_on>
          <update_rate>30</update_rate>
          <visualize>true</visualize>
          <topic>altimeter</topic>
          <enable_metrics>true</enable_metrics>
          <altimeter>
            <vertical_position>
              <noise type="gaussian">
                <mean>0.1</mean>
                <stddev>0.2</stddev>
              </noise>
            </vertical_position>
            <vertical_velocity>
              <noise type="gaussian">
                <mean>0.2</mean>
                <stddev>0.1</stddev>
              </noise>
            </vertical_velocity>
          </altimeter>
        </sensor>
        <sensor name="air_pressure" type="air_pressure">
          <always_on>1</always_on>
          <update_rate>30</update_rate>
          <visualize>true</visualize>
          <topic>air_pressure</topic>
          <enable_metrics>true</enable_metrics>
          <air_pressure>
            <reference_altitude>123</reference_altitude>
            <pressure>
              <noise type="gaussian">
                <mean>0.2</mean>
                <stddev>0.1</stddev>
              </noise>
            </pressure>
          </air_pressure>
        </sensor>
        <sensor name="imu" type="imu">
          <always_on>1</always_on>
          <update_rate>100</update_rate>
          <visualize>true</visualize>
          <topic>imu</topic>
          <enable_metrics>true</enable_metrics>
        </sensor>
        <sensor name="magnetometer" type="magnetometer">
          <always_on>1</always_on>
          <update_rate>100</update_rate>
          <visualize>true</visualize>
          <topic>magnetometer</topic>
          <enable_metrics>true</enable_metrics>
          <magnetometer>
            <x>
              <noise type="gaussian">
                <mean>0.0</mean>
                <stddev>0.1</stddev>
              </noise>
            </x>
            <y>
              <noise type="gaussian">
                <mean>0.0</mean>
                <stddev>0.1</stddev>
              </noise>
            </y>
            <z>
              <noise type="gaussian">
                <mean>0.0</mean>
                <stddev>0.1</stddev>
              </noise>
            </z>
          </magnetometer>
        </sensor>
      </link>
      <joint name="sensor_box_joint" type="fixed">
        <parent>chassis</parent>
        <child>sensor_box</child>
        <pose>-1.47 0.225 1.95 0 0 0</pose>
      </joint>
      


      <link name='front_left_wheel'>
        <pose>0 0 0 0 0 0</pose>
        <!-- <inertial auto="true" /> -->
        <inertial>
          <pose>-1.13 -0.15 0.25 0 0 0</pose>
          <mass>20</mass>
          <inertia>
            <ixx>1</ixx>
            <ixy>0</ixy>
            <ixz>0</ixz>
            <iyy>1</iyy>
            <iyz>0</iyz>
            <izz>1</izz>
          </inertia>
        </inertial>
        <visual name='visual'>
          <geometry>
          <mesh>
            <scale>.01 .01 .01</scale>
            <uri>wheel1_1.stl</uri>
          </mesh>
        </geometry>
          <material>
            <ambient>0.2 0.2 0.2 1</ambient>
            <diffuse>0.2 0.2 0.2 1</diffuse>
            <specular>0.2 0.2 0.2 1</specular>
          </material>
        </visual>
        <collision name='collision'>
          <!-- <density>3405.18</density> -->
          <geometry>
          <mesh>
            <scale>.01 .01 .01</scale>
            <uri>wheel1_1.stl</uri>
          </mesh>
        </geometry>
          <surface>
            <friction>
              <ode>
                <mu>0.5</mu>
                <mu2>1.0</mu2>
                <fdir1>0 0 1</fdir1>
              </ode>
            </friction>
          </surface>
        </collision>
      </link>

      <link name='rear_left_wheel'>
        <pose>0 0 0 0 0 0</pose>
        <!-- <inertial auto="true" /> -->
        <inertial>
          <pose>0.045 -0.15 .25 0 0 0</pose>
          <mass>20</mass>
          <inertia>
            <ixx>1</ixx>
            <ixy>0</ixy>
            <ixz>0</ixz>
            <iyy>1</iyy>
            <iyz>0</iyz>
            <izz>1</izz>
          </inertia>
        </inertial>
        <gravity>true</gravity>
        <visual name='visual'>
          <geometry>
          <mesh>
            <scale>.01 .01 .01</scale>
            <uri>wheel3_1.stl</uri>
          </mesh>
        </geometry>
          <material>
            <ambient>0.2 0.2 0.2 1</ambient>
            <diffuse>0.2 0.2 0.2 1</diffuse>
            <specular>0.2 0.2 0.2 1</specular>
          </material>
        </visual>
        <collision name='collision'>
          <!-- <density>3405.18</density> -->
          <geometry>
          <mesh>
            <scale>.01 .01 .01</scale>
            <uri>wheel3_1.stl</uri>
          </mesh>
        </geometry>
          <surface>
            <friction>
              <ode>
                <mu>0.5</mu>
                <mu2>1.0</mu2>
                <fdir1>0 0 1</fdir1>
              </ode>
            </friction>
          </surface>
        </collision>
      </link>

      <link name='front_right_wheel'>
        <pose>0 0 0 0 0 0</pose>
        <!-- <inertial auto="true" /> -->
        <inertial>
          <pose>-1.13 0.6 0.25 0 0 0</pose>
          <mass>20</mass>
          <inertia>
            <ixx>1</ixx>
            <ixy>0</ixy>
            <ixz>0</ixz>
            <iyy>1</iyy>
            <iyz>0</iyz>
            <izz>1</izz>
          </inertia>
        </inertial>
        <visual name='visual'>
          <geometry>
          <mesh>
            <scale>.01 .01 .01</scale>
            <uri>wheel2_1.stl</uri>
          </mesh>
        </geometry>
          <material>
            <ambient>0.2 0.2 0.2 1</ambient>
            <diffuse>0.2 0.2 0.2 1</diffuse>
            <specular>0.2 0.2 0.2 1</specular>
          </material>
        </visual>
        <collision name='collision'>
          <!-- <density>3405.18</density> -->
          <geometry>
          <mesh>
            <scale>.01 .01 .01</scale>
            <uri>wheel2_1.stl</uri>
          </mesh>
        </geometry>
          <surface>
            <friction>
              <ode>
                <mu>0.5</mu>
                <mu2>1.0</mu2>
                <fdir1>0 0 1</fdir1>
              </ode>
            </friction>
          </surface>
        </collision>
      </link>

      <link name='rear_right_wheel'>
        <pose>0 0 0 0 0 0</pose>
        <!-- <inertial auto="true" /> -->
        <inertial>
          <pose>0.045 0.6 .25 0 0 0</pose>
          <mass>20</mass>
          <inertia>
            <ixx>1</ixx>
            <ixy>0</ixy>
            <ixz>0</ixz>
            <iyy>1</iyy>
            <iyz>0</iyz>
            <izz>1</izz>
          </inertia>
        </inertial>
        <visual name='visual'>
          <geometry>
          <mesh>
            <scale>.01 .01 .01</scale>
            <uri>wheel4_1.stl</uri>
          </mesh>
        </geometry>
          <material>
            <ambient>0.2 0.2 0.2 1</ambient>
            <diffuse>0.2 0.2 0.2 1</diffuse>
            <specular>0.2 0.2 0.2 1</specular>
          </material>
        </visual>
        <collision name='collision'>
          <!-- <density>3405.18</density> -->
          <geometry>
          <mesh>
            <scale>.01 .01 .01</scale>
            <uri>wheel4_1.stl</uri>
          </mesh>
        </geometry>
          <surface>
            <friction>
              <ode>
                <mu>0.5</mu>
                <mu2>1.0</mu2>
                <fdir1>0 0 1</fdir1>
              </ode>
            </friction>
          </surface>
        </collision>
      </link>

      <link name="front_left_wheel_steering_link">
        <pose>0 0 0 0 0 0</pose>
        <!-- <inertial auto="true" /> -->
        <inertial>
          <pose>-1.135 -0.065 0.25 0 0 0</pose>
          <mass>5</mass>
          <inertia>
            <ixx>1</ixx>
            <iyy>1</iyy>
            <izz>1</izz>
          </inertia>
        </inertial>
        <visual name="steering_link_visual">
          <pose>0 0 0 0 0 0</pose>
          <geometry>
            <mesh>
              <scale>.01 .01 .01</scale>
              <uri>wheel1_link_1.stl</uri>
            </mesh>
          </geometry>
          <material>
            <ambient>1 1 1</ambient>
            <diffuse>1 1 1</diffuse>
          </material>
        </visual>
        <!-- <collision>
          <density>7850</density>
          <geometry>
            <mesh>
              <scale>.01 .01 .01</scale>
              <uri>wheel1_link_1.stl</uri>
            </mesh>
          </geometry>
        </collision> -->

      </link>

      <link name="front_right_wheel_steering_link">
        <pose>0 0 0 0 0 0</pose>
        <!-- <inertial auto="true" /> -->
        <inertial>
          <pose>-1.135 0.51 0.25 0 0 0</pose>
          <mass>5</mass>
          <inertia>
            <ixx>1</ixx>
            <iyy>1</iyy>
            <izz>1</izz>
          </inertia>
        </inertial>
        <visual name="steering_link_visual">
          <pose>0 0 0 0 0 0</pose>
          <geometry>
          <mesh>
            <scale>.01 .01 .01</scale>
            <uri>wheel2_link_1.stl</uri>
          </mesh>
        </geometry>
          <material>
            <ambient>1 1 1</ambient>
            <diffuse>1 1 1</diffuse>
          </material>
        </visual>
        <!-- <collision>
          <density>7850</density>
          <geometry>
            <mesh>
              <scale>.01 .01 .01</scale>
              <uri>wheel2_link_1.stl</uri>
            </mesh>
          </geometry>
        </collision> -->
      </link>

      <joint name="front_left_wheel_steering_joint" type="revolute">
        <pose>-1.135 -0.065 0.25 0 0 0</pose>
        <child>front_left_wheel_steering_link</child>
        <parent>chassis</parent>
        <axis>
          <xyz>0 0 1</xyz>
          <limit>
            <lower>-0.6</lower>
            <upper>+0.6</upper>
            <velocity>1.0</velocity>
            <effort>25</effort>
          </limit>
          <!-- <use_parent_model_frame>1</use_parent_model_frame> -->
        </axis>
      </joint>

      <joint name="front_right_wheel_steering_joint" type="revolute">
        <pose>-1.135 0.51 0.25 0 0 0</pose>
        <parent>chassis</parent>
        <child>front_right_wheel_steering_link</child>
        <axis>
          <xyz>0 0 1</xyz>
          <limit>
            <lower>-0.6</lower>
            <upper>+0.6</upper>
            <velocity>1.0</velocity>
            <effort>25</effort>
          </limit>
        </axis>
      </joint>

      <joint name='front_left_wheel_joint' type='revolute'>
        <pose>-1.13 -0.15 0.25 0 0 0</pose>
        <parent>front_left_wheel_steering_link</parent>
        <child>front_left_wheel</child>
        <axis>
          <xyz>0 1 0</xyz>
          <limit>
            <lower>-1.79769e+308</lower>
            <upper>1.79769e+308</upper>
          </limit>
        </axis>
      </joint>

      <joint name='front_right_wheel_joint' type='revolute'>
        <pose>-1.13 0.6 0.25 0 0 0</pose>
        <parent>front_right_wheel_steering_link</parent>
        <child>front_right_wheel</child>
        <axis>
          <xyz>0 1 0</xyz>
          <limit>
            <lower>-1.79769e+308</lower>
            <upper>1.79769e+308</upper>
          </limit>
        </axis>
      </joint>

      <joint name='rear_left_wheel_joint' type='revolute'>
        <pose>0.045 -0.15 .25 0 0 0</pose>
        <parent>chassis</parent>
        <child>rear_left_wheel</child>
        <axis>
          <xyz>0 1 0</xyz>
          <limit>
            <lower>-1.79769e+308</lower>
            <upper>1.79769e+308</upper>
          </limit>
        </axis>
      </joint>

      <joint name='rear_right_wheel_joint' type='revolute'>
        <pose>0.045 0.6 .25 0 0 0</pose>
        <parent>chassis</parent>
        <child>rear_right_wheel</child>
        <axis>
          <xyz>0 1 0</xyz>
          <limit>
            <lower>-1.79769e+308</lower>
            <upper>1.79769e+308</upper>
          </limit>
        </axis>
      </joint>

      <plugin
        filename="ignition-gazebo-ackermann-steering-system"
        name="gz::sim::systems::AckermannSteering">
        <left_joint>front_left_wheel_joint</left_joint>
        <left_joint>rear_left_wheel_joint</left_joint>
        <right_joint>front_right_wheel_joint</right_joint>
        <right_joint>rear_right_wheel_joint</right_joint>
        <left_steering_joint>front_left_wheel_steering_joint</left_steering_joint>
        <right_steering_joint>front_right_wheel_steering_joint</right_steering_joint>
        <kingpin_width>0.215</kingpin_width>
        <steering_limit>0.6</steering_limit>
        <wheel_base>1.175</wheel_base>
        <wheel_separation>0.75</wheel_separation>
        <wheel_radius>0.3</wheel_radius>
        <min_velocity>-5</min_velocity>
        <max_velocity>22</max_velocity>
        <min_acceleration>-3</min_acceleration>
        <max_acceleration>3</max_acceleration>
        <!-- <commandSubTopic>cmd_vel</commandSubTopic> -->

      </plugin>

    </model>

  </world>
</sdf>
